Workbook
Name A: Planilha1!$B$20:$E$23
Name AR: Planilha1!$P$21
Name B: Planilha1!$T$26:$V$28
Name far: Planilha1!$N$23
Name HRES: Planilha1!$P$17
Name N: Planilha1!$T$13:$V$13
Name N0: Planilha1!$H$37:$K$39
Name near: Planilha1!$N$22
Name u: Planilha1!$T$23:$V$23
Name V: Planilha1!$T$19:$V$19
Name VRES: Planilha1!$N$17
Name YY: Planilha1!$T$17:$V$17

Sheet Planilha2
A4: OBJETO - Cubo:
B5: A | C5: B | D5: C | E5: D | F5: E | G5: F | H5: G | I5: H
A6: x | B6: 0 | C6: 1 | D6: 0 | E6: 1 | F6: 0 | G6: 1 | H6: 0 | I6: 1
A7: y | B7: 0 | C7: 0 | D7: 1 | E7: 1 | F7: 0 | G7: 0 | H7: 1 | I7: 1
A8: z | B8: 0 | C8: 0 | D8: 0 | E8: 0 | F8: 1 | G8: 1 | H8: 1 | I8: 1
A9: h | B9: 1 | C9: 1 | D9: 1 | E9: 1 | F9: 1 | G9: 1 | H9: 1 | I9: 1
A20: A = | B20: {=TRANSPOSE(Planilha1!B20:E23)} -> 1 | C20: 0 | D20: 0 | E20: -30 | G20: matriz final | H20: {=MMULT(_xlfn.ANCHORARRAY(B55),MMULT(_xlfn.ANCHORARRAY(B45),MMULT(_xlfn.ANCHORARRAY(B40),MMULT(B60:E63,MMULT(_xlfn.ANCHORARRAY(B50),MMULT(_xlfn.ANCHORARRAY(B30),MMULT(_xlfn.ANCHORARRAY(B35),MMULT(_xlfn.ANCHORARRAY(B25),_xlfn.ANCHORARRAY(B20)))))))))} -> -0.0078919863 | I20: -0.016162552 | J20: -0.043408626 | K20: 5.2241243
B21: 0 | C21: 1 | D21: 0 | E21: -40 | H21: 0.019224884 | I21: 0.019270744 | J21: 0.065629777 | K21: -7.9105539
B22: 0 | C22: 0 | D22: 1 | E22: -100 | H22: 0.0036637363 | I22: 0.0048007579 | J22: 0.012507238 | K22: -1.7193328
B23: 0 | C23: 0 | D23: 0 | E23: 1 | H23: 0.0021982418 | I23: 0.0028804547 | J23: 0.0075043426 | K23: -0.9315997
A25: B = | B25: {=TRANSPOSE(Planilha1!B25:E28)} -> 0.9596 | C25: 0 | D25: -0.281 | E25: 0
B26: -0.09716921 | C26: 0.93836183 | D26: -0.33171558 | E26: 0 | H26: {=MMULT(_xlfn.ANCHORARRAY(H20),B6:I9)} -> 5.2241243 | I26: 5.2162323 | J26: 5.2079617 | K26: 5.2000697 | L26: 5.1807156 | M26: 5.1728237 | N26: 5.1645531 | O26: 5.1566611
B27: 0.26378901 | C27: 0.34565457 | D27: 0.90052111 | E27: 0 | H27: -7.9105539 | I27: -7.8913291 | J27: -7.8912832 | K27: -7.8720583 | L27: -7.8449242 | M27: -7.8256993 | N27: -7.8256534 | O27: -7.8064285
B28: 0 | C28: 0 | D28: 0 | E28: 1 | H28: -1.7193328 | I28: -1.7156691 | J28: -1.7145321 | K28: -1.7108683 | L28: -1.7068256 | M28: -1.7031619 | N28: -1.7020248 | O28: -1.6983611
H29: -0.9315997 | I29: -0.92940146 | J29: -0.92871925 | K29: -0.92652101 | L29: -0.92409536 | M29: -0.92189712 | N29: -0.92121491 | O29: -0.91901666
A30: D = | B30: {=TRANSPOSE(Planilha1!B30:E33)} -> 0.00046296296 | C30: 0 | D30: 0 | E30: 0
B31: 0 | C31: 0.00069444444 | D31: 0 | E31: 0
B32: 0 | C32: 0 | D32: 0.0083333333 | E32: 0
B33: 0 | C33: 0 | D33: 0 | E33: 1
A35: C = | B35: {=TRANSPOSE(Planilha1!B35:E38)} -> 1 | C35: 0 | D35: -11 | E35: 0
B36: 0 | C36: 1 | D36: -12 | E36: 0
B37: 0 | C37: 0 | D37: 1 | E37: 0
B38: 0 | C38: 0 | D38: 0 | E38: 1
A40: K = | B40: {=TRANSPOSE(Planilha1!B60:E63)} -> 0.5 | C40: 0 | D40: 0 | E40: 0.5
B41: 0 | C41: 0.5 | D41: 0 | E41: 0.5
B42: 0 | C42: 0 | D42: 1 | E42: 0
B43: 0 | C43: 0 | D43: 0 | E43: 1
A45: L = | B45: {=TRANSPOSE(Planilha1!B65:E68)} -> 20 | C45: 0 | D45: 0 | E45: -10
B46: 0 | C46: 16 | D46: 0 | E46: -8
B47: 0 | C47: 0 | D47: 0.83333333 | E47: 0.16666667
B48: 0 | C48: 0 | D48: 0 | E48: 1
A50: P = | B50: {=TRANSPOSE(Planilha1!B70:E73)} -> 1 | C50: 0 | D50: 0 | E50: 0
B51: 0 | C51: 1 | D51: 0 | E51: 0
B52: 0 | C52: 0 | D52: 1.2 | E52: -0.2
B53: 0 | C53: 0 | D53: 1 | E53: 0
A55: M = | B55: {=TRANSPOSE(Planilha1!B75:E78)} -> 1 | C55: 0 | D55: 0 | E55: 0.5
B56: 0 | C56: 1 | D56: 0 | E56: 0.5
B57: 0 | C57: 0 | D57: 1 | E57: 0.5
B58: 0 | C58: 0 | D58: 0 | E58: 1
A60: J = | B60: 1 | C60: 0 | D60: 0 | E60: 0
...

Sheet Planilha1
A1: Arthur Angelo Cenci Silva
A2: Lucas Ivanov Costa
A3: Vinicius Eduardo Morais Oliveira
A4: Vinicius Vieira Viana
A6: OBJETO - Cubo:
B7: A | C7: B | D7: C | E7: D | F7: E | G7: F | H7: G | I7: H
A8: x | B8: 0 | C8: 1 | D8: 0 | E8: 1 | F8: 0 | G8: 1 | H8: 0 | I8: 1
A9: y | B9: 0 | C9: 0 | D9: 1 | E9: 1 | F9: 0 | G9: 0 | H9: 1 | I9: 1
A10: z | B10: 0 | C10: 0 | D10: 0 | E10: 0 | F10: 1 | G10: 1 | H10: 1 | I10: 1
A11: h | B11: 1 | C11: 1 | D11: 1 | E11: 1 | F11: 1 | G11: 1 | H11: 1 | I11: 1
A12: VRP = | B12: 30 | C12: 40 | D12: 100
H13: LIMITES DA WINDOW | M13: CENTRO DO PLANO DE PROJEÇÃO | S13: N = | T13: {=B12:D12-B14:D14} -> 29 | U13: 38 | V13: 99
A14: P = | B14: 1 | C14: 2 | D14: 1 | H14: Xmin = | I14: -10 | J14: Xmax = | K14: 10 | M14: CU = | N14: =(I20+K20)/2 -> 550
H15: Ymin | I15: -8 | J15: Ymax = | K15: 8 | M15: CV = | N15: =(K21+I21)/2 -> 600 | S15: ^n = | T15: {=_xlfn.ANCHORARRAY(T13)/SQRT(T13^2+U13^2+V13^2)} -> 0.26378901 | U15: 0.34565457 | V15: 0.90052111
A16: Y = | B16: 0 | C16: 1 | D16: 0
H17: Zmin = | I17: =near/far -> 0.16666667 | J17: Zmax = | K17: 1 | M17: VRES = | N17: 900 | O17: HRES = | P17: 600 | S17: Y' = | T17: {=SUMPRODUCT(B16:D16,_xlfn.ANCHORARRAY(T15))*_xlfn.ANCHORARRAY(T15)} -> 0.091179878 | U17: 0.11947708 | V17: 0.31126924
A19: THE VIEWING TRANSFORMATION | H19: LIMITES DA VIEWPORT | M19: RAZÃO DE ASPECTO | S19: V = | T19: {=B16:D16-_xlfn.ANCHORARRAY(T17)} -> -0.091179878 | U19: 0.88052292 | V19: -0.31126924
A20: A = | B20: 1 | C20: 0 | D20: 0 | E20: 0 | H20: Umin = | I20: 100 | J20: Umax = | K20: 1000 | M20: SU = | N20: =K20-I20 -> 900
B21: 0 | C21: 1 | D21: 0 | E21: 0 | H21: Vmin = | I21: 300 | J21: Vmax = | K21: 900 | M21: SV = | N21: =K21-I21 -> 600 | P21: =N20/N21 -> 1.5 | S21: ^v = | T21: {=_xlfn.ANCHORARRAY(T19)/SQRT(T19^2+U19^2+V19^2)} -> -0.09716921 | U21: 0.93836183 | V21: -0.33171558
B22: 0 | C22: 0 | D22: 1 | E22: 0 | M22: N = | N22: 20
B23: {=-B12:D12} -> -30 | C23: -40 | D23: -100 | E23: 1 | H23: DP = | I23: 50 | M23: F = | N23: 120 | S23: û = | T23: 0.9596 | U23: 0 | V23: -0.281
A25: B = | B25: {=B} -> 0.9596 | C25: -0.09716921 | D25: 0.26378901 | E25: 0
B26: 0 | C26: 0.93836183 | D26: 0.34565457 | E26: 0 | M26: PAR = | N26: =AR*(VRES/HRES) -> 2.25 | S26: B = | T26: {=TRANSPOSE(u)} -> 0.9596 | U26: {=TRANSPOSE(_xlfn.ANCHORARRAY(T21))} -> -0.09716921 | V26: {=TRANSPOSE(_xlfn.ANCHORARRAY(T15))} -> 0.26378901
B27: -0.281 | C27: -0.33171558 | D27: 0.90052111 | E27: 0 | G27: NL = | H27: {=MMULT(B20:E23,B25:E28)} -> 0.9596 | I27: -0.09716921 | J27: 0.26378901 | K27: 0 | T27: 0 | U27: 0.93836183 | V27: 0.34565457
B28: 0 | C28: 0 | D28: 0 | E28: 1 | H28: 0 | I28: 0.93836183 | J28: 0.34565457 | K28: 0 | T28: -0.281 | U28: -0.33171558 | V28: 0.90052111
H29: -0.281 | I29: -0.33171558 | J29: 0.90052111 | K29: 0
A30: D = | B30: =I23/(N20*N23) -> 0.00046296296 | C30: 0 | D30: 0 | E30: 0 | H30: -0.688 | I30: -1.4478389 | J30: -111.79196 | K30: 1
B31: 0 | C31: =I23/(N21*N23) -> 0.00069444444 | D31: 0 | E31: 0
B32: 0 | C32: 0 | D32: =1/N23 -> 0.0083333333 | E32: 0 | G32: NR = | H32: {=MMULT(B40:E43,B45:E48)} -> 0.41666667 | I32: 0 | J32: 0 | K32: 0
B33: 0 | C33: 0 | D33: 0 | E33: 1 | H33: 0 | I33: 0.41666667 | J33: 0 | K33: 0
H34: 0 | I34: 0 | J34: 0.0083333333 | K34: 0
A35: C = | B35: 1 | C35: 0 | D35: 0 | E35: 0 | H35: 0 | I35: 0 | J35: 0 | K35: 1
B36: 0 | C36: 1 | D36: 0 | E36: 0 | T36: NPS= | U36: {=MMULT(_xlfn.ANCHORARRAY(H42),MMULT(B70:E73,_xlfn.ANCHORARRAY(N50)))} -> 0.011981167 | V36: 0.0026145345 | W36: 0.0043964836 | X36: 0.0026378901
B37: =-N14/I23 -> -11 | C37: =-N15/I23 -> -12 | D37: 1 | E37: 0 | G37: NOR = | H37: =1/N20 -> 0.0011111111 | I37: 0 | J37: 0 | K37: 0 | U37: 0.0017282728 | V37: -0.010783218 | W37: 0.0057609095 | X37: 0.0034565457
B38: 0 | C38: 0 | D38: 0 | E38: 1 | H38: 0 | I38: =1/N21 -> 0.0016666667 | J38: 0 | K38: 0 | U38: 0.0013803833 | V38: 0.00892548 | W38: 0.015008685 | X38: 0.0090052111
H39: 0 | I39: 0 | J39: =1/(far-near) -> 0.01 | K39: 0 | U39: -6.7777154 | V39: 7.3603447 | W39: -2.3631994 | X39: -1.3179196
A40: E = | B40: =1/far -> 0.0083333333 | C40: 0 | D40: 0 | E40: 0 | H40: =-N14/N20 -> -0.61111111 | I40: =-N15/N21 -> -1 | J40: =-near/(far-near) -> -0.2 | K40: 1
B41: 0 | C41: =1/far -> 0.0083333333 | D41: 0 | E41: 0
B42: 0 | C42: 0 | D42: =1/far -> 0.0083333333 | E42: 0 | G42: NO = | H42: {=MMULT(_xlfn.ANCHORARRAY(H27),H37:K40)} -> 0.0010662222 | I42: -0.00016194868 | J42: 0.0026378901 | K42: 0
B43: 0 | C43: 0 | D43: 0 | E43: 1 | H43: 0 | I43: 0.0015639364 | J43: 0.0034565457 | K43: 0
...
